Workbook

Sheet Sheet1
B3: Case 1. ESG 정량 지표 | I3: Case2. 대면 시 비용 절감 효과 비교 (단위 : 원)
B4: 항목 | C4: 변수 | D4: 단위 | E4: 결 과 값 | G4: 비고 | I4: 항목 | J4: 왕복교통비 | K4: 출장 숙박비 | L4: 출장 식비 | M4: 총 소요 비용 | N4: 절감 % | O4: 비고
B5: CO2 배출 감소 | C5: =Assumptions!D6 -> 20000 | D5: 0.00864 | E5: =C5*D5 -> 172.8 | G5: 단위값 : kg | I5: 대면서명 | J5: =Assumptions!D9 -> 50000 | K5: =Assumptions!D10 -> 50000 | L5: =Assumptions!D11 -> 20000 | M5: =J5+K5+L5 -> 120000 | N5: =(M5-M6)/M5 -> 0.99333333 | O5: *교통비 : SRT 기준 서울↔지방
B6: 나무 보호 효과 | C6: =Assumptions!D6 -> 20000 | D6: 0.00036 | E6: =C6*D6 -> 7.2 | G6: 단위값 : 그루 | I6: 전자서명 | J6: X | K6: X | L6: X | M6: =Assumptions!D17 -> 800 | O6: * 1만 건 구매 기준 건당 비용
B7: 물 절약 | C7: =Assumptions!D6 -> 20000 | D7: 10 | E7: =C7*D7 -> 200000 | G7: 단위값 : 리터(L)
B8: 산출 근거 : KEI(한국환경연구원) 연구 기준
I9: Case3. 등기(우체국) 계약 시 비용 절감 효과 비교 (단위 : 원)
I10: 항목 | J10: 왕복교통비 | K10: 등기비용 | L10: 시급 | M10: 총 소요 비용 | N10: 절감 % | O10: 비고
I11: 등기서명 | J11: =Assumptions!D13 -> 3000 | K11: =Assumptions!D14 -> 3800 | L11: =Assumptions!D15 -> 10030 | M11: =J11+K11+L11 -> 16830 | N11: =(M11-M12)/M11 -> 0.95246583 | O11: ㅁ 등기 업무 1시간 가정 - 교통비 : 버스비 왕복(3,000원) - 등기비 : 익일특급 기준) - 시급 : 2025년 최저 시급 기준
I12: 전자서명 | J12: X | K12: X | L12: X | M12: =Assumptions!D17 -> 800 | O12: * 1만 건 구매 기준 건당 비용
I13: * 시급의 경우, 담당자 우체국 방문 시 타 업무 진행 불가능을 이유로 계산식에 산정
B16: ㅁ 산출 전제 - 1만 건 사용 예정 + 1개 템플릿 A4 2장 구성으로 가정 후 계산 * 총 2만 장 절약(A4 기준) ㅁ 변수 처리 - 노란색 채우기 부분 변수 입력 시, 자동 계산 | I16: Case4. 업무 시간 절감 효과 (단위 : 1 업무일, 8시간)
I17: 항목 | J17: 계약 예상 시간 | K17: 보관 시간 | L17: 총 업무시간 | M17: 시간 절감(항목 대비) | N17: - | O17: 비고
I18: 대면계약 | J18: 1 | K18: =10/(8*60) -> 0.020833333 | L18: =J18+K18 -> 1.0208333 | M18: =(L18-$L$20)/L18 -> 0.99795918
I19: 등기계약 | J19: =1/8 -> 0.125 | K19: =10/(8*60) -> 0.020833333 | L19: =J19+K19 -> 0.14583333 | M19: =(L19-$L$20)/L19 -> 0.98571429
I20: 전자계약 | J20: =1/(8*60) -> 0.0020833333 | K20: X | L20: =J20 -> 0.0020833333 | M20: - | O20: ㅁ 단건 1분, 다건 2분 소요(평균) ㅁ 문서 완료 시, 자동 보관
I24: #결과 : 총 비용 및 업무 시간 절감 (단위 : 원/업무일)
I25: 항목 | J25: 전환 퍼센테지 | K25: 절감비용 | L25: 절감 업무일 | M25: 템플릿(계약) 수 | N25: 총 절감 비용 | O25: 총 절감 업무일
I26: 대면계약 | J26: =Assumptions!D7 -> 0.5 | K26: =(M5-M6)*J26 -> 59600 | L26: =(L18-L20)*J26 -> 0.509375 | M26: =10000*J26 -> 5000 | N26: =K26*M26 -> 298000000 | O26: =L26*M26 -> 2546.875
I27: 등기계약 | J27: =Assumptions!D8 -> 0.5 | K27: =(M11-M12)*J27 -> 8015 | L27: =(L19-L20)*J27 -> 0.071875 | M27: =10000*J27 -> 5000 | N27: =K27*M27 -> 40075000 | O27: =L27*M27 -> 359.375
I28: 합 계 | J28: =J26+J27 -> 1 | K28: =K26+K27 -> 67615 | L28: =L26+L27 -> 0.58125 | M28: 10000 | N28: =N26+N27 -> 338075000 | O28: =O26+O27 -> 2906.25
I29: * 1만 건 계약 예정으로, 템플릿 수(=계약서 수) 1만 건 계산식에 상정
I31: 기타 : 종이 문서 위험 비용 제로화
I32: ㅁ 보관 비용 제로 ㅁ A4 용지 구매 비용 제로 ㅁ 원본 훼손/분실 위험 제로 ㅁ 문서 미교부 위험 제로 ㅁ 문서 오기입/미기입으로 인한 재진행 비용 제로 ㅁ 원본 문서를 찾기 위한 시간 제로 ㅁ API 연동 시, 완료된 문서 시스템 기입/이동 시간 제로

Sheet Claude Log
A1: Turn # | B1: Timestamp | C1: Action Type | D1: Summary | E1: Details | F1: References
A2: 1 | B2: 46048 | C2: Analysis | D2: ROI 계산식 검토 및 개선점 분석 | E2: 오타, 변수관리, 수식일관성, 추가기능 제안 | F2: Sheet1!B3:O38
A3: 2 | B3: 46048 | C3: Created | D3: 전체 개선사항 반영 완료 | E3: 1) 오타수정(제로), 2) % 포맷통일, 3) Assumptions 시트, 4) 민감도 분석 테이블 | F3: Sheet1!I32, N5, N11 / Assumptions!B2:G38
A4: 3 | B4: 46048 | C4: Created | D4: Sheet1↔Assumptions 연동, ROI, 차트데이터 | E4: 1) 변수 연동(C5:C7,J5:L5,J11:L11,J26:J27,M6,M12), 2) ROI분석(8,352%), 3) 차트데이터 | F4: Sheet1, Assumptions!B40:F50, I19:L38
A5: 4 | B5: 46048 | C5: Guide | D5: 차트 생성 가이드 추가 | E5: 차트 데이터 준비 완료, 수동 생성 가이드 제공 | F5: Assumptions!I40:L45
A6: 5 | B6: 46048 | C6: Modified | D6: 차트 데이터 분리 및 개선 | E6: 차트A(절감비용), 차트B(절감연수) 데이터 분리, X축 라벨 텍스트화 | F6: Assumptions!I52:M68

Sheet Assumptions
B2: 📋 주요 가정 (Assumptions)
B3: 구분 | C3: 항목 | D3: 값 | E3: 단위
B4: 계약 기본 | C4: 총 계약 건수 | D4: 10000 | E4: 건
C5: 템플릿당 A4 장수 | D5: 2 | E5: 장
C6: 총 A4 절약 장수 | D6: =D4*D5 -> 20000 | E6: 장
B7: 계약 유형 비율 | C7: 대면계약 비율 | D7: 0.5
C8: 등기계약 비율 | D8: 0.5
B9: 대면계약 비용 | C9: 왕복교통비 | D9: 50000 | E9: 원
C10: 출장 숙박비 | D10: 50000 | E10: 원
C11: 출장 식비 | D11: 20000 | E11: 원
C12: ▶ 대면 총비용 | D12: =D9+D10+D11 -> 120000 | E12: 원
B13: 등기계약 비용 | C13: 왕복교통비(버스) | D13: 3000 | E13: 원
C14: 등기비용(익일특급) | D14: 3800 | E14: 원
C15: 시급(2025 최저시급) | D15: 10030 | E15: 원
C16: ▶ 등기 총비용 | D16: =D13+D14+D15 -> 16830 | E16: 원
B17: 전자서명 | C17: 건당 비용 | D17: 800 | E17: 원
B19: 📊 민감도 분석 - 계약 건수별 절감 효과
B20: 계약 건수 | C20: 대면 절감비용 | D20: 등기 절감비용 | E20: 총 절감비용 | F20: 절감 업무일 | G20: 절감 연수 | H20: 비고
B21: 1000 | C21: =($D$12-$D$17)*$D$7*B21 -> 59600000 | D21: =($D$16-$D$17)*$D$8*B21 -> 8015000 | E21: =C21+D21 -> 67615000 | F21: =((1.02083-0.00208)*$D$7+(0.14583-0.00208)*$D$8)*B21 -> 581.25 | G21: =F21/250 -> 2.325
B22: 3000 | C22: =($D$12-$D$17)*$D$7*B22 -> 178800000 | D22: =($D$16-$D$17)*$D$8*B22 -> 24045000 | E22: =C22+D22 -> 202845000 | F22: =((1.02083-0.00208)*$D$7+(0.14583-0.00208)*$D$8)*B22 -> 1743.75 | G22: =F22/250 -> 6.975
B23: 5000 | C23: =($D$12-$D$17)*$D$7*B23 -> 298000000 | D23: =($D$16-$D$17)*$D$8*B23 -> 40075000 | E23: =C23+D23 -> 338075000 | F23: =((1.02083-0.00208)*$D$7+(0.14583-0.00208)*$D$8)*B23 -> 2906.25 | G23: =F23/250 -> 11.625
B24: 10000 | C24: =($D$12-$D$17)*$D$7*B24 -> 596000000 | D24: =($D$16-$D$17)*$D$8*B24 -> 80150000 | E24: =C24+D24 -> 676150000 | F24: =((1.02083-0.00208)*$D$7+(0.14583-0.00208)*$D$8)*B24 -> 5812.5 | G24: =F24/250 -> 23.25 | H24: ← 현재 기준
B25: 20000 | C25: =($D$12-$D$17)*$D$7*B25 -> 1192000000 | D25: =($D$16-$D$17)*$D$8*B25 -> 160300000 | E25: =C25+D25 -> 1352300000 | F25: =((1.02083-0.00208)*$D$7+(0.14583-0.00208)*$D$8)*B25 -> 11625 | G25: =F25/250 -> 46.5
B26: 50000 | C26: =($D$12-$D$17)*$D$7*B26 -> 2980000000 | D26: =($D$16-$D$17)*$D$8*B26 -> 400750000 | E26: =C26+D26 -> 3380750000 | F26: =((1.02083-0.00208)*$D$7+(0.14583-0.00208)*$D$8)*B26 -> 29062.5 | G26: =F26/250 -> 116.25
B27: 100000 | C27: =($D$12-$D$17)*$D$7*B27 -> 5960000000 | D27: =($D$16-$D$17)*$D$8*B27 -> 801500000 | E27: =C27+D27 -> 6761500000 | F27: =((1.02083-0.00208)*$D$7+(0.14583-0.00208)*$D$8)*B27 -> 58125 | G27: =F27/250 -> 232.5
B28: 200000 | C28: =($D$12-$D$17)*$D$7*B28 -> 11920000000 | D28: =($D$16-$D$17)*$D$8*B28 -> 1603000000 | E28: =C28+D28 -> 13523000000 | F28: =((1.02083-0.00208)*$D$7+(0.14583-0.00208)*$D$8)*B28 -> 116250 | G28: =F28/250 -> 465
B30: 📈 대면/등기 비율별 절감 효과 (10,000건 기준)
B31: 대면 비율 | C31: 등기 비율 | D31: 대면 절감(억) | E31: 등기 절감(억) | F31: 총 절감(억) | G31: 기준 대비
B32: 1 | C32: 0 | D32: =($D$12-$D$17)*1*$D$4/100000000 -> 11.92 | E32: =($D$16-$D$17)*0*$D$4/100000000 -> 0 | F32: =D32+E32 -> 11.92 | G32: =F32-$F$35 -> 5.1585
B33: 0.8 | C33: 0.2 | D33: =($D$12-$D$17)*0.8*$D$4/100000000 -> 9.536 | E33: =($D$16-$D$17)*0.2*$D$4/100000000 -> 0.3206 | F33: =D33+E33 -> 9.8566 | G33: =F33-$F$35 -> 3.0951
B34: 0.6 | C34: 0.4 | D34: =($D$12-$D$17)*0.6*$D$4/100000000 -> 7.152 | E34: =($D$16-$D$17)*0.4*$D$4/100000000 -> 0.6412 | F34: =D34+E34 -> 7.7932 | G34: =F34-$F$35 -> 1.0317
B35: 0.5 | C35: 0.5 | D35: =($D$12-$D$17)*0.5*$D$4/100000000 -> 5.96 | E35: =($D$16-$D$17)*0.5*$D$4/100000000 -> 0.8015 | F35: =D35+E35 -> 6.7615 | G35: ← 현재
B36: 0.3 | C36: 0.7 | D36: =($D$12-$D$17)*0.3*$D$4/100000000 -> 3.576 | E36: =($D$16-$D$17)*0.7*$D$4/100000000 -> 1.1221 | F36: =D36+E36 -> 4.6981 | G36: =F36-$F$35 -> -2.0634
B37: 0.2 | C37: 0.8 | D37: =($D$12-$D$17)*0.2*$D$4/100000000 -> 2.384 | E37: =($D$16-$D$17)*0.8*$D$4/100000000 -> 1.2824 | F37: =D37+E37 -> 3.6664 | G37: =F37-$F$35 -> -3.0951
B38: 0 | C38: 1 | D38: =($D$12-$D$17)*0*$D$4/100000000 -> 0 | E38: =($D$16-$D$17)*1*$D$4/100000000 -> 1.603 | F38: =D38+E38 -> 1.603 | G38: =F38-$F$35 -> -5.1585
B40: 💰 ROI 분석 (투자 대비 수익률) | I40: 🔄 도입 전/후 비교
B41: 항목 | C41: 값 | D41: 단위 | E41: 비고 | I41: 항목 | J41: 도입 전 | K41: 도입 후 | L41: 절감률
B42: 이폼사인 연간 비용 | C42: 8000000 | D42: 원 | E42: ※ 예상 비용 입력 | I42: 건당 비용(원) | J42: =D12*D7+D16*D8 -> 68415 | K42: =D17 -> 800 | L42: =(J42-K42)/J42 -> 0.98830666
B43: 연간 절감 비용 | C43: =E24 -> 676150000 | D43: 원 | E43: 10,000건 기준 | I43: 연간 총비용(억) | J43: =J42*D4/100000000 -> 6.8415 | K43: =K42*D4/100000000 -> 0.08 | L43: =(J43-K43)/J43 -> 0.98830666
B44: 순 절감액 | C44: =C43-C42 -> 668150000 | D44: 원 | E44: =절감비용-이폼사인비용 | I44: 처리 시간(분/건) | J44: =(1.02083*60)*D7+(0.14583*60)*D8 -> 34.9998 | K44: 1 | L44: =(J44-K44)/J44 -> 0.97142841
...
